<?xml version="1.0" ?>
<!-- =================================================================================== -->
<!-- |    This document was autogenerated by xacro from /homes/gwalck/work/dev/catkin_ws_indigo/src/shadow_robot/sr_description/robots/shadowhand_motor.urdf.xacro | -->
<!-- |    EDITING THIS FILE BY HAND IS NOT RECOMMENDED                                 | -->
<!-- =================================================================================== -->
<robot name="shadowhand_motor" xmlns:body="http://playerstage.sourceforge.net/gazebo/xmlschema/#body" xmlns:controller="http://playerstage.sourceforge.net/gazebo/xmlschema/#controller" xmlns:geom="http://playerstage.sourceforge.net/gazebo/xmlschema/#geom" xmlns:interface="http://playerstage.sourceforge.net/gazebo/xmlschema/#interface" xmlns:joint="http://playerstage.sourceforge.net/gazebo/xmlschema/#slider" xmlns:sensor="http://playerstage.sourceforge.net/gazebo/xmlschema/#sensor" xmlns:xacro="http://ros.org/wiki/xacro">
  <material name="Blue">
    <color rgba="0.0 0.0 0.8 1.0"/>
  </material>
  <material name="Green">
    <color rgba="0.0 0.8 0.0 1.0"/>
  </material>
  <material name="BiotacGreen">
    <color rgba="0.31 0.85 0.42 1.0"/>
  </material>
  <material name="Grey">
    <color rgba="0.2 0.2 0.2 1.0"/>
  </material>
  <material name="LightGrey">
    <color rgba="0.6 0.6 0.6 1.0"/>
  </material>
  <material name="Red">
    <color rgba="0.8 0.0 0.0 1.0"/>
  </material>
  <material name="White">
    <color rgba="1.0 1.0 1.0 1.0"/>
  </material>
 <link name="world"/>
  <joint name="arm_base_joint" type="revolute">
    <parent link="world"/>
    <child link="forearm"/>
    <origin rpy="1.5707 0 -1.5707" xyz="0 0 1.3"/>
    <axis xyz="0 0 1"/>
    <limit effort="10000.000000" lower="0.0" upper="0.0" velocity="-1"/>
    <dynamics damping="1.0"/>
  </joint>
 <gazebo reference="arm_base_joint">
    <stopCfm value="0.01"/>
    <stopErp value="0"/>
    <provideFeedback>1</provideFeedback>
    <implicitSpringDamper>1</implicitSpringDamper>
  </gazebo>

  <gazebo>
    <plugin filename="libsr_gazebo_ros_controller_manager.so" name="sr_gazebo_ros_controller_manager">
      <alwaysOn>true</alwaysOn>
      <updateRate>1400.0</updateRate>
      <!-- <robotParam>sh_description</robotParam> -->
    </plugin>
  </gazebo>
  <link name="forearm">
    <inertial>
      <origin rpy="0 0 0" xyz="0 0 0.09"/>
      <mass value="3.0"/>
      <inertia ixx="0.001" ixy="0.0" ixz="0.0" iyy="0.001" iyz="0.0" izz="0.001"/>
    </inertial>
    <visual>
      <origin rpy="0 0 0" xyz="0 0 0"/>
      <geometry name="forearm_visual">
        <mesh filename="package://sr_description/hand/model/forearm.dae" scale="0.001 0.001 0.001"/>
      </geometry>
      <material name="Grey"/>
    </visual>
    <collision>
      <origin rpy="0 0 0" xyz="0 0 0.092"/>
      <geometry name="forearm_collision">
        <box size="0.140 0.140 0.184"/>
      </geometry>
    </collision>
    <!-- wrist mount -->
    <collision>
      <origin rpy="0 0.78 0" xyz="0 -0.01 0.181"/>
      <geometry>
        <box size="0.07 0.07 0.07"/>
      </geometry>
    </collision>
  </link>
  <gazebo reference="forearm">
    <material>LightGrey</material>
    <selfCollide>false</selfCollide>
  </gazebo>
  <link name="wrist">
    <inertial>
      <origin rpy="0 0 0" xyz="0 0 0"/>
      <mass value="0.1"/>
      <inertia ixx="0.000120" ixy="0.0" ixz="0.0" iyy="0.000148" iyz="0.0" izz="0.0000438"/>
    </inertial>
    <visual>
      <origin rpy="0 0 0" xyz="0 0 0"/>
      <geometry name="wrist_visual">
        <mesh filename="package://sr_description/hand/model/wrist.dae" scale="0.001 0.001 0.001"/>
      </geometry>
      <material name="LightGrey"/>
    </visual>
    <collision>
      <origin rpy="1.5708 1.5708 0 " xyz="0 0 0"/>
      <geometry name="wrist_collision_geom">
        <cylinder length="0.030" radius="0.0135"/>
      </geometry>
    </collision>
    <collision>
      <origin rpy="0 1.5708 0" xyz="-0.026 0 0.034"/>
      <geometry>
        <cylinder length="0.010" radius="0.011"/>
      </geometry>
    </collision>
    <collision>
      <origin rpy="0 1.5708 0" xyz="0.031 0 0.034"/>
      <geometry>
        <cylinder length="0.010" radius="0.011"/>
      </geometry>
    </collision>
    <collision>
      <origin rpy="0 0.7854 0" xyz="-0.021 0 0.011"/>
      <geometry>
        <box size="0.027 0.018 0.010"/>
      </geometry>
    </collision>
    <collision>
      <origin rpy="0 -0.7854 0" xyz="0.026 0 0.010"/>
      <geometry>
        <box size="0.027 0.018 0.010"/>
      </geometry>
    </collision>
  </link>
  <gazebo reference="wrist">
    <material>Gazebo/White</material>
    <selfCollide>false</selfCollide>
  </gazebo>
  <joint name="WRJ2" type="revolute">
    <parent link="forearm"/>
    <child link="wrist"/>
    <origin rpy="0 0 0" xyz="0 -0.010 0.213"/>
    <axis xyz="0 1.0 0"/>
    <limit effort="1000" lower="-0.523598775598" upper="0.174532925199" velocity="10.0"/>
    <dynamics damping="1.0"/>
  </joint>
  <transmission name="wrist_transmission" type="sr_mechanism_model/SimpleTransmission">
    <actuator name="WRJ2"/>
    <joint name="WRJ2"/>
  </transmission>
  <link name="palm">
    <inertial>
      <origin rpy="0 0 0" xyz="0 0 0.035"/>
      <mass value="0.3"/>
      <inertia ixx="0.00013581" ixy="0.0" ixz="0.0" iyy="0.000185" iyz="0.0" izz="0.0000725"/>
    </inertial>
    <visual>
      <origin rpy="0 0 0" xyz="0 0 0"/>
      <geometry name="palm_visual">
        <mesh filename="package://sr_description/hand/model/palm.dae" scale="0.001 0.001 0.001"/>
      </geometry>
      <material name="Grey"/>
    </visual>
    <collision>
      <origin rpy="0 0 0" xyz="0.011 0.0085 0.038"/>
      <geometry name="palm_collision_geom">
        <box size="0.062 0.007 0.098"/>
      </geometry>
    </collision>
    <collision>
      <origin rpy="0 0 0" xyz="0.0005 -0.0035 0.038"/>
      <geometry>
        <box size="0.041 0.017 0.098"/>
      </geometry>
    </collision>
    <!-- palm complement below first finger -->
    <collision>
      <origin rpy="0 0 0" xyz="0.0315 -0.0035 0.073"/>
      <geometry>
        <box size="0.021 0.017 0.028"/>
      </geometry>
    </collision>
    <!-- thumb pulp side -->
    <collision>
      <origin rpy="0 0 0" xyz="0.0315 -0.0085 0.001"/>
      <geometry>
        <box size="0.021 0.027 0.024"/>
      </geometry>
    </collision>
    <!-- thumb pulp central -->
    <collision>
      <origin rpy="0 0 0" xyz="0.01 -0.017 0.011"/>
      <geometry>
        <box size="0.022 0.010 0.044"/>
      </geometry>
    </collision>
    <!-- above middle finger-->
    <collision>
      <origin rpy="0 0 0" xyz="0.011 0 0.089"/>
      <geometry>
        <box size="0.018 0.024 0.004"/>
      </geometry>
    </collision>
    <!-- metacarpal side-->
    <collision>
      <origin rpy="0 0 0" xyz="-0.03 0 0.009"/>
      <geometry>
        <box size="0.020 0.024 0.040"/>
      </geometry>
    </collision>
  </link>
  <joint name="WRJ1" type="revolute">
    <parent link="wrist"/>
    <child link="palm"/>
    <origin rpy="0 0 0" xyz="0 0 0.034"/>
    <axis xyz="1 0 0"/>
    <limit effort="1000" lower="-0.698131700798" upper="0.488692190558" velocity="10.0"/>
    <dynamics damping="1.0"/>
  </joint>
  <transmission name="palm_transmission" type="sr_mechanism_model/SimpleTransmission">
    <actuator name="WRJ1"/>
    <joint name="WRJ1"/>
  </transmission>
  <gazebo reference="palm">
    <sensor name="palm_contact" type="contact">
      <always_on>1</always_on>
      <update_rate>1000.0</update_rate>
      <contact>
        <collision>palm_collision</collision>
        <topic>palm_collision</topic>
      </contact>
      <plugin filename="libgazebo_ros_bumper.so" name="palm_gazebo_ros_bumper_controller">
        <alwaysOn>true</alwaysOn>
        <frameName>palm</frameName>
        <updateRate>100.0</updateRate>
        <bumperTopicName>contacts/palm</bumperTopicName>
      </plugin>
    </sensor>
    <material>LightGrey</material>
  </gazebo>
  <link name="ffknuckle">
    <inertial>
      <origin rpy="0 0 0" xyz="0 0 0"/>
      <!--<insert_block name="origin" /> -->
      <mass value="0.008"/>
      <inertia ixx="0.0000002" ixy="0.0" ixz="0.0" iyy="0.0000002" iyz="0.0" izz="0.0000002"/>
    </inertial>
    <visual>
      <origin rpy="0 0 0" xyz="0 0 0.0005"/>
      <geometry name="ffknuckle_visual">
        <mesh filename="package://sr_description/hand/model/knuckle.dae" scale="0.001 0.001 0.001"/>
      </geometry>
      <material name="LightGrey"/>
    </visual>
    <collision>
      <origin rpy="0 1.5708 0" xyz="0 0 0"/>
      <geometry name="ffknuckle_collision_geom">
        <cylinder length="0.014" radius="0.007"/>
      </geometry>
    </collision>
  </link>
  <joint name="FFJ4" type="revolute">
    <parent link="palm"/>
    <child link="ffknuckle"/>
    <!--<origin xyz="0.033 0 0.095" rpy="0 0 0" />-->
    <origin rpy="0 0 0" xyz="0.033 0 0.095"/>
    <axis xyz="0 -1.0 0"/>
    <limit effort="1000" lower="-0.349065850399" upper="0.349065850399" velocity="10.0"/>
    <dynamics damping="1.0"/>
  </joint>
  <transmission name="ffknuckle_transmission" type="sr_mechanism_model/SimpleTransmission">
    <actuator name="FFJ4"/>
    <joint name="FFJ4"/>
  </transmission>
  <gazebo reference="ffknuckle">
    <sensor name="ffknuckle_contact" type="contact">
      <always_on>1</always_on>
      <update_rate>1000.0</update_rate>
      <contact>
        <collision>ffknuckle_collision</collision>
        <topic>ffknuckle_collision</topic>
      </contact>
      <plugin filename="libgazebo_ros_bumper.so" name="ffknuckle_gazebo_ros_bumper_controller">
        <alwaysOn>true</alwaysOn>
        <frameName>ffknuckle</frameName>
        <updateRate>100.0</updateRate>
        <bumperTopicName>contacts/ff/knuckle</bumperTopicName>
      </plugin>
    </sensor>
    <material>Gazebo/Grey</material>
  </gazebo>
  <link name="ffproximal">
    <inertial>
      <mass value="0.014"/>
      <origin xyz="0 0 0.0225"/>
      <inertia ixx="0.0000010" ixy="0.0" ixz="0.0" iyy="0.0000010" iyz="0.0" izz="0.0000005"/>
    </inertial>
    <visual>
      <origin rpy="0 0 0" xyz="0 0 0"/>
      <geometry name="ffproximal_visual">
        <mesh filename="package://sr_description/hand/model/F3.dae" scale="0.001 0.001 0.001"/>
      </geometry>
      <material name="Grey"/>
    </visual>
    <collision>
      <origin rpy="0 0 0 " xyz="0 0 0.025"/>
      <geometry name="ffproximal_collision_geom">
        <cylinder length="0.040" radius="0.007"/>
      </geometry>
    </collision>
  </link>
  <joint name="FFJ3" type="revolute">
    <parent link="ffknuckle"/>
    <child link="ffproximal"/>
    <origin rpy="0 0 0" xyz="0 0 0"/>
    <axis xyz="1 0 0"/>
    <limit effort="1000" lower="0" upper="1.57079632679" velocity="10.0"/>
    <dynamics damping="1.0"/>
  </joint>
  <transmission name="ffproximal_transmission" type="sr_mechanism_model/SimpleTransmission">
    <actuator name="FFJ3"/>
    <joint name="FFJ3"/>
  </transmission>
  <gazebo reference="ffproximal">
    <sensor name="ffproximal_contact" type="contact">
      <always_on>1</always_on>
      <update_rate>1000.0</update_rate>
      <contact>
        <collision>ffproximal_collision</collision>
        <topic>ffproximal_collision</topic>
      </contact>
      <plugin filename="libgazebo_ros_bumper.so" name="ffproximal_gazebo_ros_bumper_controller">
        <alwaysOn>true</alwaysOn>
        <frameName>ffproximal</frameName>
        <updateRate>100.0</updateRate>
        <bumperTopicName>contacts/ff/proximal</bumperTopicName>
      </plugin>
    </sensor>
    <material>LightGrey</material>
    <selfCollide>true</selfCollide>
  </gazebo>
  <link name="ffmiddle">
    <inertial>
      <origin rpy="0 0 0" xyz="0 0 0.0125"/>
      <mass value="0.012"/>
      <inertia ixx="0.0000008" ixy="0.0" ixz="0.0" iyy="0.0000008" iyz="0.0" izz="0.0000003"/>
    </inertial>
    <visual>
      <origin rpy="0 0 0" xyz="0 0 0"/>
      <geometry name="ffmiddle_visual">
        <mesh filename="package://sr_description/hand/model/F2.dae" scale="0.001 0.001 0.001"/>
      </geometry>
      <material name="Grey"/>
    </visual>
    <collision>
      <origin rpy="0 0 0 " xyz="0 0 0.0125"/>
      <geometry name="ffmiddle_collision_geom">
        <cylinder length="0.025" radius="0.007"/>
      </geometry>
    </collision>
    <collision>
      <origin rpy="0 0 0 " xyz="0 0 0.0"/>
      <geometry>
        <sphere radius="0.007"/>
      </geometry>
    </collision>
    <collision>
      <origin rpy="0 0 0 " xyz="0 0 0.025"/>
      <geometry>
        <sphere radius="0.007"/>
      </geometry>
    </collision>
  </link>
  <joint name="FFJ2" type="revolute">
    <parent link="ffproximal"/>
    <child link="ffmiddle"/>
    <origin rpy="0 0 0" xyz="0 0 0.045"/>
    <axis xyz="1 0 0"/>
    <limit effort="1000" lower="0" upper="1.57079632679" velocity="10.0"/>
    <dynamics damping="1.0"/>
  </joint>
  <transmission name="ffmiddle_transmission" type="sr_mechanism_model/J0Transmission">
    <actuator name="FFJ0"/>
    <joint name="FFJ1"/>
    <joint name="FFJ2"/>
  </transmission>
  <gazebo reference="ffmiddle">
    <sensor name="ffmiddle_contact" type="contact">
      <always_on>1</always_on>
      <update_rate>1000.0</update_rate>
      <contact>
        <collision>ffmiddle_collision</collision>
        <topic>ffmiddle_collision</topic>
      </contact>
      <plugin filename="libgazebo_ros_bumper.so" name="ffproximal_gazebo_ros_bumper_controller">
        <alwaysOn>true</alwaysOn>
        <frameName>ffmiddle</frameName>
        <updateRate>100.0</updateRate>
        <bumperTopicName>contacts/ff/middle</bumperTopicName>
      </plugin>
    </sensor>
    <material>LightGrey</material>
    <selfCollide>true</selfCollide>
  </gazebo>
  <link name="ffdistal">
    <inertial>
      <mass value="0.010"/>
      <origin xyz="0 0 0.013"/>
      <inertia ixx="0.0000001" ixy="0.0" ixz="0.0" iyy="0.0000001" iyz="0.0" izz="0.0000001"/>
    </inertial>
    <visual>
      <origin rpy="0 0 0" xyz="0 0 0"/>
      <geometry name="ffdistal_visual">
        <mesh filename="package://sr_description/hand/model/F1.dae" scale="0.001 0.001 0.001"/>
      </geometry>
      <material name="Grey"/>
    </visual>
    <collision>
      <origin rpy="0 0 0" xyz="0 0 0"/>
      <geometry name="ffdistal_collision_geom">
        <mesh filename="package://sr_description/hand/model/F1.dae" scale="0.001 0.001 0.001"/>
      </geometry>
    </collision>
  </link>
  <joint name="FFJ1" type="revolute">
    <parent link="ffmiddle"/>
    <child link="ffdistal"/>
    <origin rpy="0 0 0" xyz="0 0 0.025"/>
    <axis xyz="1 0 0"/>
    <limit effort="1000" lower="0" upper="1.57079632679" velocity="10.0"/>
    <dynamics damping="1.0"/>
  </joint>
  <link name="fftip">
    <inertial>
      <mass value="0.001"/>
      <inertia ixx="0.0000001" ixy="0.0" ixz="0.0" iyy="0.0000001" iyz="0.0" izz="0.0000001"/>
    </inertial>
  </link>
  <joint name="FFtip" type="fixed">
    <parent link="ffdistal"/>
    <child link="fftip"/>
    <origin rpy="0 0 0" xyz="0 0 0.026"/>
  </joint>
  <gazebo reference="ffdistal">
    <sensor name="ffdistal_contact" type="contact">
      <always_on>1</always_on>
      <update_rate>1000.0</update_rate>
      <contact>
        <collision>ffdistal_collision</collision>
        <topic>ffdistal_collision</topic>
      </contact>
      <plugin filename="libgazebo_ros_bumper.so" name="ffdistal_gazebo_ros_bumper_controller">
        <alwaysOn>true</alwaysOn>
        <frameName>ffdistal</frameName>
        <updateRate>100.0</updateRate>
        <bumperTopicName>contacts/ff/distal</bumperTopicName>
      </plugin>
    </sensor>
    <mu1 value="500.0"/>
    <mu2 value="500.0"/>
    <kp value="10000000.0"/>
    <kd value="1.0"/>
    <material>LightGrey</material>
    <selfCollide>true</selfCollide>
  </gazebo>
  <link name="mfknuckle">
    <inertial>
      <origin rpy="0 0 0" xyz="0 0 0"/>
      <!--<insert_block name="origin" /> -->
      <mass value="0.008"/>
      <inertia ixx="0.0000002" ixy="0.0" ixz="0.0" iyy="0.0000002" iyz="0.0" izz="0.0000002"/>
    </inertial>
    <visual>
      <origin rpy="0 0 0" xyz="0 0 0.0005"/>
      <geometry name="mfknuckle_visual">
        <mesh filename="package://sr_description/hand/model/knuckle.dae" scale="0.001 0.001 0.001"/>
      </geometry>
      <material name="LightGrey"/>
    </visual>
    <collision>
      <origin rpy="0 1.5708 0" xyz="0 0 0"/>
      <geometry name="mfknuckle_collision_geom">
        <cylinder length="0.014" radius="0.007"/>
      </geometry>
    </collision>
  </link>
  <joint name="MFJ4" type="revolute">
    <parent link="palm"/>
    <child link="mfknuckle"/>
    <!--<origin xyz="0.033 0 0.095" rpy="0 0 0" />-->
    <origin rpy="0 0 0" xyz="0.011 0 0.099"/>
    <axis xyz="0 -1.0 0"/>
    <limit effort="1000" lower="-0.349065850399" upper="0.349065850399" velocity="10.0"/>
    <dynamics damping="1.0"/>
  </joint>
  <transmission name="mfknuckle_transmission" type="sr_mechanism_model/SimpleTransmission">
    <actuator name="MFJ4"/>
    <joint name="MFJ4"/>
  </transmission>
  <gazebo reference="mfknuckle">
    <sensor name="mfknuckle_contact" type="contact">
      <always_on>1</always_on>
      <update_rate>1000.0</update_rate>
      <contact>
        <collision>mfknuckle_collision</collision>
        <topic>mfknuckle_collision</topic>
      </contact>
      <plugin filename="libgazebo_ros_bumper.so" name="mfknuckle_gazebo_ros_bumper_controller">
        <alwaysOn>true</alwaysOn>
        <frameName>mfknuckle</frameName>
        <updateRate>100.0</updateRate>
        <bumperTopicName>contacts/mf/knuckle</bumperTopicName>
      </plugin>
    </sensor>
    <material>Gazebo/Grey</material>
  </gazebo>
  <link name="mfproximal">
    <inertial>
      <mass value="0.014"/>
      <origin xyz="0 0 0.0225"/>
      <inertia ixx="0.0000010" ixy="0.0" ixz="0.0" iyy="0.0000010" iyz="0.0" izz="0.0000005"/>
    </inertial>
    <visual>
      <origin rpy="0 0 0" xyz="0 0 0"/>
      <geometry name="mfproximal_visual">
        <mesh filename="package://sr_description/hand/model/F3.dae" scale="0.001 0.001 0.001"/>
      </geometry>
      <material name="Grey"/>
    </visual>
    <collision>
      <origin rpy="0 0 0 " xyz="0 0 0.025"/>
      <geometry name="mfproximal_collision_geom">
        <cylinder length="0.040" radius="0.007"/>
      </geometry>
    </collision>
  </link>
  <joint name="MFJ3" type="revolute">
    <parent link="mfknuckle"/>
    <child link="mfproximal"/>
    <origin rpy="0 0 0" xyz="0 0 0"/>
    <axis xyz="1 0 0"/>
    <limit effort="1000" lower="0" upper="1.57079632679" velocity="10.0"/>
    <dynamics damping="1.0"/>
  </joint>
  <transmission name="mfproximal_transmission" type="sr_mechanism_model/SimpleTransmission">
    <actuator name="MFJ3"/>
    <joint name="MFJ3"/>
  </transmission>
  <gazebo reference="mfproximal">
    <sensor name="mfproximal_contact" type="contact">
      <always_on>1</always_on>
      <update_rate>1000.0</update_rate>
      <contact>
        <collision>mfproximal_collision</collision>
        <topic>mfproximal_collision</topic>
      </contact>
      <plugin filename="libgazebo_ros_bumper.so" name="mfproximal_gazebo_ros_bumper_controller">
        <alwaysOn>true</alwaysOn>
        <frameName>mfproximal</frameName>
        <updateRate>100.0</updateRate>
        <bumperTopicName>contacts/mf/proximal</bumperTopicName>
      </plugin>
    </sensor>
    <material>LightGrey</material>
    <selfCollide>true</selfCollide>
  </gazebo>
  <link name="mfmiddle">
    <inertial>
      <origin rpy="0 0 0" xyz="0 0 0.0125"/>
      <mass value="0.012"/>
      <inertia ixx="0.0000008" ixy="0.0" ixz="0.0" iyy="0.0000008" iyz="0.0" izz="0.0000003"/>
    </inertial>
    <visual>
      <origin rpy="0 0 0" xyz="0 0 0"/>
      <geometry name="mfmiddle_visual">
        <mesh filename="package://sr_description/hand/model/F2.dae" scale="0.001 0.001 0.001"/>
      </geometry>
      <material name="Grey"/>
    </visual>
    <collision>
      <origin rpy="0 0 0 " xyz="0 0 0.0125"/>
      <geometry name="mfmiddle_collision_geom">
        <cylinder length="0.025" radius="0.007"/>
      </geometry>
    </collision>
    <collision>
      <origin rpy="0 0 0 " xyz="0 0 0.0"/>
      <geometry>
        <sphere radius="0.007"/>
      </geometry>
    </collision>
    <collision>
      <origin rpy="0 0 0 " xyz="0 0 0.025"/>
      <geometry>
        <sphere radius="0.007"/>
      </geometry>
    </collision>
  </link>
  <joint name="MFJ2" type="revolute">
    <parent link="mfproximal"/>
    <child link="mfmiddle"/>
    <origin rpy="0 0 0" xyz="0 0 0.045"/>
    <axis xyz="1 0 0"/>
    <limit effort="1000" lower="0" upper="1.57079632679" velocity="10.0"/>
    <dynamics damping="1.0"/>
  </joint>
  <transmission name="mfmiddle_transmission" type="sr_mechanism_model/J0Transmission">
    <actuator name="MFJ0"/>
    <joint name="MFJ1"/>
    <joint name="MFJ2"/>
  </transmission>
  <gazebo reference="mfmiddle">
    <sensor name="mfmiddle_contact" type="contact">
      <always_on>1</always_on>
      <update_rate>1000.0</update_rate>
      <contact>
        <collision>mfmiddle_collision</collision>
        <topic>mfmiddle_collision</topic>
      </contact>
      <plugin filename="libgazebo_ros_bumper.so" name="mfproximal_gazebo_ros_bumper_controller">
        <alwaysOn>true</alwaysOn>
        <frameName>mfmiddle</frameName>
        <updateRate>100.0</updateRate>
        <bumperTopicName>contacts/mf/middle</bumperTopicName>
      </plugin>
    </sensor>
    <material>LightGrey</material>
    <selfCollide>true</selfCollide>
  </gazebo>
  <link name="mfdistal">
    <inertial>
      <mass value="0.010"/>
      <origin xyz="0 0 0.013"/>
      <inertia ixx="0.0000001" ixy="0.0" ixz="0.0" iyy="0.0000001" iyz="0.0" izz="0.0000001"/>
    </inertial>
    <visual>
      <origin rpy="0 0 0" xyz="0 0 0"/>
      <geometry name="mfdistal_visual">
        <mesh filename="package://sr_description/hand/model/F1.dae" scale="0.001 0.001 0.001"/>
      </geometry>
      <material name="Grey"/>
    </visual>
    <collision>
      <origin rpy="0 0 0" xyz="0 0 0"/>
      <geometry name="mfdistal_collision_geom">
        <mesh filename="package://sr_description/hand/model/F1.dae" scale="0.001 0.001 0.001"/>
      </geometry>
    </collision>
  </link>
  <joint name="MFJ1" type="revolute">
    <parent link="mfmiddle"/>
    <child link="mfdistal"/>
    <origin rpy="0 0 0" xyz="0 0 0.025"/>
    <axis xyz="1 0 0"/>
    <limit effort="1000" lower="0" upper="1.57079632679" velocity="10.0"/>
    <dynamics damping="1.0"/>
  </joint>
  <link name="mftip">
    <inertial>
      <mass value="0.001"/>
      <inertia ixx="0.0000001" ixy="0.0" ixz="0.0" iyy="0.0000001" iyz="0.0" izz="0.0000001"/>
    </inertial>
  </link>
  <joint name="MFtip" type="fixed">
    <parent link="mfdistal"/>
    <child link="mftip"/>
    <origin rpy="0 0 0" xyz="0 0 0.026"/>
  </joint>
  <gazebo reference="mfdistal">
    <sensor name="mfdistal_contact" type="contact">
      <always_on>1</always_on>
      <update_rate>1000.0</update_rate>
      <contact>
        <collision>mfdistal_collision</collision>
        <topic>mfdistal_collision</topic>
      </contact>
      <plugin filename="libgazebo_ros_bumper.so" name="mfdistal_gazebo_ros_bumper_controller">
        <alwaysOn>true</alwaysOn>
        <frameName>mfdistal</frameName>
        <updateRate>100.0</updateRate>
        <bumperTopicName>contacts/mf/distal</bumperTopicName>
      </plugin>
    </sensor>
    <mu1 value="500.0"/>
    <mu2 value="500.0"/>
    <kp value="10000000.0"/>
    <kd value="1.0"/>
    <material>LightGrey</material>
    <selfCollide>true</selfCollide>
  </gazebo>
  <link name="rfknuckle">
    <inertial>
      <origin rpy="0 0 0" xyz="0 0 0"/>
      <!--<insert_block name="origin" /> -->
      <mass value="0.008"/>
      <inertia ixx="0.0000002" ixy="0.0" ixz="0.0" iyy="0.0000002" iyz="0.0" izz="0.0000002"/>
    </inertial>
    <visual>
      <origin rpy="0 0 0" xyz="0 0 0.0005"/>
      <geometry name="rfknuckle_visual">
        <mesh filename="package://sr_description/hand/model/knuckle.dae" scale="0.001 0.001 0.001"/>
      </geometry>
      <material name="LightGrey"/>
    </visual>
    <collision>
      <origin rpy="0 1.5708 0" xyz="0 0 0"/>
      <geometry name="rfknuckle_collision_geom">
        <cylinder length="0.014" radius="0.007"/>
      </geometry>
    </collision>
  </link>
  <joint name="RFJ4" type="revolute">
    <parent link="palm"/>
    <child link="rfknuckle"/>
    <!--<origin xyz="0.033 0 0.095" rpy="0 0 0" />-->
    <origin rpy="0 0 0" xyz="-0.011 0 0.095"/>
    <axis xyz="0 1.0 0"/>
    <limit effort="1000" lower="-0.349065850399" upper="0.349065850399" velocity="10.0"/>
    <dynamics damping="1.0"/>
  </joint>
  <transmission name="rfknuckle_transmission" type="sr_mechanism_model/SimpleTransmission">
    <actuator name="RFJ4"/>
    <joint name="RFJ4"/>
  </transmission>
  <gazebo reference="rfknuckle">
    <sensor name="rfknuckle_contact" type="contact">
      <always_on>1</always_on>
      <update_rate>1000.0</update_rate>
      <contact>
        <collision>rfknuckle_collision</collision>
        <topic>rfknuckle_collision</topic>
      </contact>
      <plugin filename="libgazebo_ros_bumper.so" name="rfknuckle_gazebo_ros_bumper_controller">
        <alwaysOn>true</alwaysOn>
        <frameName>rfknuckle</frameName>
        <updateRate>100.0</updateRate>
        <bumperTopicName>contacts/rf/knuckle</bumperTopicName>
      </plugin>
    </sensor>
    <material>Gazebo/Grey</material>
  </gazebo>
  <link name="rfproximal">
    <inertial>
      <mass value="0.014"/>
      <origin xyz="0 0 0.0225"/>
      <inertia ixx="0.0000010" ixy="0.0" ixz="0.0" iyy="0.0000010" iyz="0.0" izz="0.0000005"/>
    </inertial>
    <visual>
      <origin rpy="0 0 0" xyz="0 0 0"/>
      <geometry name="rfproximal_visual">
        <mesh filename="package://sr_description/hand/model/F3.dae" scale="0.001 0.001 0.001"/>
      </geometry>
      <material name="Grey"/>
    </visual>
    <collision>
      <origin rpy="0 0 0 " xyz="0 0 0.025"/>
      <geometry name="rfproximal_collision_geom">
        <cylinder length="0.040" radius="0.007"/>
      </geometry>
    </collision>
  </link>
  <joint name="RFJ3" type="revolute">
    <parent link="rfknuckle"/>
    <child link="rfproximal"/>
    <origin rpy="0 0 0" xyz="0 0 0"/>
    <axis xyz="1 0 0"/>
    <limit effort="1000" lower="0" upper="1.57079632679" velocity="10.0"/>
    <dynamics damping="1.0"/>
  </joint>
  <transmission name="rfproximal_transmission" type="sr_mechanism_model/SimpleTransmission">
    <actuator name="RFJ3"/>
    <joint name="RFJ3"/>
  </transmission>
  <gazebo reference="rfproximal">
    <sensor name="rfproximal_contact" type="contact">
      <always_on>1</always_on>
      <update_rate>1000.0</update_rate>
      <contact>
        <collision>rfproximal_collision</collision>
        <topic>rfproximal_collision</topic>
      </contact>
      <plugin filename="libgazebo_ros_bumper.so" name="rfproximal_gazebo_ros_bumper_controller">
        <alwaysOn>true</alwaysOn>
        <frameName>rfproximal</frameName>
        <updateRate>100.0</updateRate>
        <bumperTopicName>contacts/rf/proximal</bumperTopicName>
      </plugin>
    </sensor>
    <material>LightGrey</material>
    <selfCollide>true</selfCollide>
  </gazebo>
  <link name="rfmiddle">
    <inertial>
      <origin rpy="0 0 0" xyz="0 0 0.0125"/>
      <mass value="0.012"/>
      <inertia ixx="0.0000008" ixy="0.0" ixz="0.0" iyy="0.0000008" iyz="0.0" izz="0.0000003"/>
    </inertial>
    <visual>
      <origin rpy="0 0 0" xyz="0 0 0"/>
      <geometry name="rfmiddle_visual">
        <mesh filename="package://sr_description/hand/model/F2.dae" scale="0.001 0.001 0.001"/>
      </geometry>
      <material name="Grey"/>
    </visual>
    <collision>
      <origin rpy="0 0 0 " xyz="0 0 0.0125"/>
      <geometry name="rfmiddle_collision_geom">
        <cylinder length="0.025" radius="0.007"/>
      </geometry>
    </collision>
    <collision>
      <origin rpy="0 0 0 " xyz="0 0 0.0"/>
      <geometry>
        <sphere radius="0.007"/>
      </geometry>
    </collision>
    <collision>
      <origin rpy="0 0 0 " xyz="0 0 0.025"/>
      <geometry>
        <sphere radius="0.007"/>
      </geometry>
    </collision>
  </link>
  <joint name="RFJ2" type="revolute">
    <parent link="rfproximal"/>
    <child link="rfmiddle"/>
    <origin rpy="0 0 0" xyz="0 0 0.045"/>
    <axis xyz="1 0 0"/>
    <limit effort="1000" lower="0" upper="1.57079632679" velocity="10.0"/>
    <dynamics damping="1.0"/>
  </joint>
  <transmission name="rfmiddle_transmission" type="sr_mechanism_model/J0Transmission">
    <actuator name="RFJ0"/>
    <joint name="RFJ1"/>
    <joint name="RFJ2"/>
  </transmission>
  <gazebo reference="rfmiddle">
    <sensor name="rfmiddle_contact" type="contact">
      <always_on>1</always_on>
      <update_rate>1000.0</update_rate>
      <contact>
        <collision>rfmiddle_collision</collision>
        <topic>rfmiddle_collision</topic>
      </contact>
      <plugin filename="libgazebo_ros_bumper.so" name="rfproximal_gazebo_ros_bumper_controller">
        <alwaysOn>true</alwaysOn>
        <frameName>rfmiddle</frameName>
        <updateRate>100.0</updateRate>
        <bumperTopicName>contacts/rf/middle</bumperTopicName>
      </plugin>
    </sensor>
    <material>LightGrey</material>
    <selfCollide>true</selfCollide>
  </gazebo>
  <link name="rfdistal">
    <inertial>
      <mass value="0.010"/>
      <origin xyz="0 0 0.013"/>
      <inertia ixx="0.0000001" ixy="0.0" ixz="0.0" iyy="0.0000001" iyz="0.0" izz="0.0000001"/>
    </inertial>
    <visual>
      <origin rpy="0 0 0" xyz="0 0 0"/>
      <geometry name="rfdistal_visual">
        <mesh filename="package://sr_description/hand/model/F1.dae" scale="0.001 0.001 0.001"/>
      </geometry>
      <material name="Grey"/>
    </visual>
    <collision>
      <origin rpy="0 0 0" xyz="0 0 0"/>
      <geometry name="rfdistal_collision_geom">
        <mesh filename="package://sr_description/hand/model/F1.dae" scale="0.001 0.001 0.001"/>
      </geometry>
    </collision>
  </link>
  <joint name="RFJ1" type="revolute">
    <parent link="rfmiddle"/>
    <child link="rfdistal"/>
    <origin rpy="0 0 0" xyz="0 0 0.025"/>
    <axis xyz="1 0 0"/>
    <limit effort="1000" lower="0" upper="1.57079632679" velocity="10.0"/>
    <dynamics damping="1.0"/>
  </joint>
  <link name="rftip">
    <inertial>
      <mass value="0.001"/>
      <inertia ixx="0.0000001" ixy="0.0" ixz="0.0" iyy="0.0000001" iyz="0.0" izz="0.0000001"/>
    </inertial>
  </link>
  <joint name="RFtip" type="fixed">
    <parent link="rfdistal"/>
    <child link="rftip"/>
    <origin rpy="0 0 0" xyz="0 0 0.026"/>
  </joint>
  <gazebo reference="rfdistal">
    <sensor name="rfdistal_contact" type="contact">
      <always_on>1</always_on>
      <update_rate>1000.0</update_rate>
      <contact>
        <collision>rfdistal_collision</collision>
        <topic>rfdistal_collision</topic>
      </contact>
      <plugin filename="libgazebo_ros_bumper.so" name="rfdistal_gazebo_ros_bumper_controller">
        <alwaysOn>true</alwaysOn>
        <frameName>rfdistal</frameName>
        <updateRate>100.0</updateRate>
        <bumperTopicName>contacts/rf/distal</bumperTopicName>
      </plugin>
    </sensor>
    <mu1 value="500.0"/>
    <mu2 value="500.0"/>
    <kp value="10000000.0"/>
    <kd value="1.0"/>
    <material>LightGrey</material>
    <selfCollide>true</selfCollide>
  </gazebo>
  <link name="lfmetacarpal">
    <inertial>
      <origin rpy="0 0 0" xyz="0 0 0.04"/>
      <mass value="0.075"/>
      <inertia ixx="5e-6" ixy="0.0" ixz="0.0" iyy="5e-6" iyz="0.0" izz="3e-6"/>
    </inertial>
    <visual>
      <origin rpy="0 0 0" xyz="0 0 0"/>
      <geometry name="lfmetacarpal_visual">
        <mesh filename="package://sr_description/hand/model/lfmetacarpal.dae" scale="0.001 0.001 0.001"/>
      </geometry>
      <material name="Grey"/>
    </visual>
    <collision>
      <origin rpy="0 0 0" xyz="0 0 0.038"/>
      <geometry name="lfmetacarpal_collision_geom">
        <box size="0.018 0.024 0.040"/>
      </geometry>
    </collision>
  </link>
  <joint name="LFJ5" type="revolute">
    <parent link="palm"/>
    <child link="lfmetacarpal"/>
    <origin rpy="0 0 0" xyz="-0.033 0 0.02071"/>
    <axis xyz="0.573576436 0 0.819152044"/>
    <limit effort="1000" lower="0" upper="0.785398163397" velocity="10.0"/>
    <dynamics damping="1.0"/>
  </joint>
  <transmission name="lfmetacarpal_transmission" type="sr_mechanism_model/SimpleTransmission">
    <actuator name="LFJ5"/>
    <joint name="LFJ5"/>
  </transmission>
  <gazebo reference="lfmetacarpal">
    <sensor name="lfmetacarpal_contact" type="contact">
      <always_on>1</always_on>
      <update_rate>1000.0</update_rate>
      <contact>
        <collision>lfmetacarpal_collision</collision>
        <topic>lfmetacarpal_collision</topic>
      </contact>
      <plugin filename="libgazebo_ros_bumper.so" name="lfmetacarpal_gazebo_ros_bumper_controller">
        <alwaysOn>true</alwaysOn>
        <frameName>lfmetacarpal</frameName>
        <updateRate>100.0</updateRate>
        <bumperTopicName>contacts/lf/metacarpal</bumperTopicName>
      </plugin>
    </sensor>
    <selfCollide>true</selfCollide>
    <material>LightGrey</material>
  </gazebo>
  <link name="lfknuckle">
    <inertial>
      <origin rpy="0 0 0" xyz="0 0 0"/>
      <!--<insert_block name="origin" /> -->
      <mass value="0.008"/>
      <inertia ixx="0.0000002" ixy="0.0" ixz="0.0" iyy="0.0000002" iyz="0.0" izz="0.0000002"/>
    </inertial>
    <visual>
      <origin rpy="0 0 0" xyz="0 0 0.0005"/>
      <geometry name="lfknuckle_visual">
        <mesh filename="package://sr_description/hand/model/knuckle.dae" scale="0.001 0.001 0.001"/>
      </geometry>
      <material name="LightGrey"/>
    </visual>
    <collision>
      <origin rpy="0 1.5708 0" xyz="0 0 0"/>
      <geometry name="lfknuckle_collision_geom">
        <cylinder length="0.014" radius="0.007"/>
      </geometry>
    </collision>
  </link>
  <joint name="LFJ4" type="revolute">
    <parent link="lfmetacarpal"/>
    <child link="lfknuckle"/>
    <!--<origin xyz="0.033 0 0.095" rpy="0 0 0" />-->
    <origin rpy="0 0 0" xyz="0 0 0.06579"/>
    <axis xyz="0 1.0 0"/>
    <limit effort="1000" lower="-0.349065850399" upper="0.349065850399" velocity="10.0"/>
    <dynamics damping="1.0"/>
  </joint>
  <transmission name="lfknuckle_transmission" type="sr_mechanism_model/SimpleTransmission">
    <actuator name="LFJ4"/>
    <joint name="LFJ4"/>
  </transmission>
  <gazebo reference="lfknuckle">
    <sensor name="lfknuckle_contact" type="contact">
      <always_on>1</always_on>
      <update_rate>1000.0</update_rate>
      <contact>
        <collision>lfknuckle_collision</collision>
        <topic>lfknuckle_collision</topic>
      </contact>
      <plugin filename="libgazebo_ros_bumper.so" name="lfknuckle_gazebo_ros_bumper_controller">
        <alwaysOn>true</alwaysOn>
        <frameName>lfknuckle</frameName>
        <updateRate>100.0</updateRate>
        <bumperTopicName>contacts/lf/knuckle</bumperTopicName>
      </plugin>
    </sensor>
    <material>Gazebo/Grey</material>
  </gazebo>
  <link name="lfproximal">
    <inertial>
      <mass value="0.014"/>
      <origin xyz="0 0 0.0225"/>
      <inertia ixx="0.0000010" ixy="0.0" ixz="0.0" iyy="0.0000010" iyz="0.0" izz="0.0000005"/>
    </inertial>
    <visual>
      <origin rpy="0 0 0" xyz="0 0 0"/>
      <geometry name="lfproximal_visual">
        <mesh filename="package://sr_description/hand/model/F3.dae" scale="0.001 0.001 0.001"/>
      </geometry>
      <material name="Grey"/>
    </visual>
    <collision>
      <origin rpy="0 0 0 " xyz="0 0 0.025"/>
      <geometry name="lfproximal_collision_geom">
        <cylinder length="0.040" radius="0.007"/>
      </geometry>
    </collision>
  </link>
  <joint name="LFJ3" type="revolute">
    <parent link="lfknuckle"/>
    <child link="lfproximal"/>
    <origin rpy="0 0 0" xyz="0 0 0"/>
    <axis xyz="1 0 0"/>
    <limit effort="1000" lower="0" upper="1.57079632679" velocity="10.0"/>
    <dynamics damping="1.0"/>
  </joint>
  <transmission name="lfproximal_transmission" type="sr_mechanism_model/SimpleTransmission">
    <actuator name="LFJ3"/>
    <joint name="LFJ3"/>
  </transmission>
  <gazebo reference="lfproximal">
    <sensor name="lfproximal_contact" type="contact">
      <always_on>1</always_on>
      <update_rate>1000.0</update_rate>
      <contact>
        <collision>lfproximal_collision</collision>
        <topic>lfproximal_collision</topic>
      </contact>
      <plugin filename="libgazebo_ros_bumper.so" name="lfproximal_gazebo_ros_bumper_controller">
        <alwaysOn>true</alwaysOn>
        <frameName>lfproximal</frameName>
        <updateRate>100.0</updateRate>
        <bumperTopicName>contacts/lf/proximal</bumperTopicName>
      </plugin>
    </sensor>
    <material>LightGrey</material>
    <selfCollide>true</selfCollide>
  </gazebo>
  <link name="lfmiddle">
    <inertial>
      <origin rpy="0 0 0" xyz="0 0 0.0125"/>
      <mass value="0.012"/>
      <inertia ixx="0.0000008" ixy="0.0" ixz="0.0" iyy="0.0000008" iyz="0.0" izz="0.0000003"/>
    </inertial>
    <visual>
      <origin rpy="0 0 0" xyz="0 0 0"/>
      <geometry name="lfmiddle_visual">
        <mesh filename="package://sr_description/hand/model/F2.dae" scale="0.001 0.001 0.001"/>
      </geometry>
      <material name="Grey"/>
    </visual>
    <collision>
      <origin rpy="0 0 0 " xyz="0 0 0.0125"/>
      <geometry name="lfmiddle_collision_geom">
        <cylinder length="0.025" radius="0.007"/>
      </geometry>
    </collision>
    <collision>
      <origin rpy="0 0 0 " xyz="0 0 0.0"/>
      <geometry>
        <sphere radius="0.007"/>
      </geometry>
    </collision>
    <collision>
      <origin rpy="0 0 0 " xyz="0 0 0.025"/>
      <geometry>
        <sphere radius="0.007"/>
      </geometry>
    </collision>
  </link>
  <joint name="LFJ2" type="revolute">
    <parent link="lfproximal"/>
    <child link="lfmiddle"/>
    <origin rpy="0 0 0" xyz="0 0 0.045"/>
    <axis xyz="1 0 0"/>
    <limit effort="1000" lower="0" upper="1.57079632679" velocity="10.0"/>
    <dynamics damping="1.0"/>
  </joint>
  <transmission name="lfmiddle_transmission" type="sr_mechanism_model/J0Transmission">
    <actuator name="LFJ0"/>
    <joint name="LFJ1"/>
    <joint name="LFJ2"/>
  </transmission>
  <gazebo reference="lfmiddle">
    <sensor name="lfmiddle_contact" type="contact">
      <always_on>1</always_on>
      <update_rate>1000.0</update_rate>
      <contact>
        <collision>lfmiddle_collision</collision>
        <topic>lfmiddle_collision</topic>
      </contact>
      <plugin filename="libgazebo_ros_bumper.so" name="lfproximal_gazebo_ros_bumper_controller">
        <alwaysOn>true</alwaysOn>
        <frameName>lfmiddle</frameName>
        <updateRate>100.0</updateRate>
        <bumperTopicName>contacts/lf/middle</bumperTopicName>
      </plugin>
    </sensor>
    <material>LightGrey</material>
    <selfCollide>true</selfCollide>
  </gazebo>
  <link name="lfdistal">
    <inertial>
      <mass value="0.010"/>
      <origin xyz="0 0 0.01"/>
      <inertia ixx="0.0000001" ixy="0.0" ixz="0.0" iyy="0.0000001" iyz="0.0" izz="0.0000001"/>
    </inertial>
    <visual>
      <origin rpy="0 0 0" xyz="0 0 0"/>
      <geometry name="lfdistal_visual">
        <mesh filename="package://sr_description/hand/model/F1.dae" scale="0.001 0.001 0.001"/>
      </geometry>
      <material name="Grey"/>
    </visual>
    <collision>
      <origin rpy="0 0 0" xyz="0 0 0"/>
      <geometry name="lfdistal_collision_geom">
        <mesh filename="package://sr_description/hand/model/F1.dae" scale="0.001 0.001 0.001"/>
      </geometry>
    </collision>
  </link>
  <joint name="LFJ1" type="revolute">
    <parent link="lfmiddle"/>
    <child link="lfdistal"/>
    <origin rpy="0 0 0" xyz="0 0 0.025"/>
    <axis xyz="1 0 0"/>
    <limit effort="1000" lower="0" upper="1.57079632679" velocity="10.0"/>
    <dynamics damping="1.0"/>
  </joint>
  <link name="lftip">
    <inertial>
      <mass value="0.001"/>
      <inertia ixx="0.0000001" ixy="0.0" ixz="0.0" iyy="0.0000001" iyz="0.0" izz="0.0000001"/>
    </inertial>
  </link>
  <joint name="LFtip" type="fixed">
    <parent link="lfdistal"/>
    <child link="lftip"/>
    <origin rpy="0 0 0" xyz="0 0 0.026"/>
  </joint>
  <gazebo reference="lfdistal">
    <sensor name="lfdistal_contact" type="contact">
      <always_on>1</always_on>
      <update_rate>1000.0</update_rate>
      <contact>
        <collision>lfdistal_collision</collision>
        <topic>lfdistal_collision</topic>
      </contact>
      <plugin filename="libgazebo_ros_bumper.so" name="lfdistal_gazebo_ros_bumper_controller">
        <alwaysOn>true</alwaysOn>
        <frameName>lfdistal</frameName>
        <updateRate>100.0</updateRate>
        <bumperTopicName>contacts/lf/distal</bumperTopicName>
      </plugin>
    </sensor>
    <mu1 value="500.0"/>
    <mu2 value="500.0"/>
    <kp value="10000000.0"/>
    <kd value="1.0"/>
    <material>LightGrey</material>
    <selfCollide>true</selfCollide>
  </gazebo>
  <link name="thbase">
    <inertial>
      <mass value="0.010"/>
      <origin rpy="0 0 0" xyz="0 0 0"/>
      <inertia ixx="1e-6" ixy="0.0" ixz="0.0" iyy="1e-6" iyz="0.0" izz="1e-6"/>
    </inertial>
    <visual>
      <origin rpy="0 0 0" xyz="0 0 0"/>
      <geometry name="thbase_visual">
        <box size="0.001 0.001 0.001"/>
      </geometry>
      <material name="shadow_thbase_material">
        <color rgba="0.5 0.5 0.5 1.0"/>
      </material>
    </visual>
    <collision>
      <origin rpy="0 0 0 " xyz="0 0 0"/>
      <geometry name="thbase_collision_geom">
        <sphere radius="0.011"/>
      </geometry>
    </collision>
  </link>
  <joint name="THJ5" type="revolute">
    <parent link="palm"/>
    <child link="thbase"/>
    <origin rpy="0 0.785398163397 0.0" xyz="0.034 -0.0085 0.029"/>
    <axis xyz="0 0 -1.0"/>
    <limit effort="1000" lower="-1.0471975512" upper="1.0471975512" velocity="10.0"/>
    <dynamics damping="1.0"/>
  </joint>
  <transmission name="thbase_transmission" type="sr_mechanism_model/SimpleTransmission">
    <actuator name="THJ5"/>
    <joint name="THJ5"/>
  </transmission>
  <gazebo reference="thbase">
    <sensor name="thbase_contact" type="contact">
      <always_on>1</always_on>
      <update_rate>1000.0</update_rate>
      <contact>
        <collision>thbase_collision</collision>
        <topic>thbase_collision</topic>
      </contact>
      <plugin filename="libgazebo_ros_bumper.so" name="thbase_gazebo_ros_bumper_controller">
        <alwaysOn>true</alwaysOn>
        <frameName>thbase</frameName>
        <updateRate>100.0</updateRate>
        <bumperTopicName>contacts/th/base</bumperTopicName>
      </plugin>
    </sensor>
    <selfCollide>false</selfCollide>
    <material>LightGrey</material>
  </gazebo>
  <link name="thproximal">
    <inertial>
      <mass value="0.016"/>
      <origin rpy="0 0 0" xyz="0 0 0.019"/>
      <inertia ixx="1e-6" ixy="0.0" ixz="0.0" iyy="1e-6" iyz="0.0" izz="1e-6"/>
    </inertial>
    <visual>
      <origin rpy="0 0 0" xyz="0 0 0"/>
      <geometry name="thproximal_visual">
        <mesh filename="package://sr_description/hand/model/TH3_z.dae" scale="0.001 0.001 0.001"/>
      </geometry>
      <material name="shadow_thproximal_material">
        <color rgba="0.2 0.2 0.2 1.0"/>
      </material>
    </visual>
    <collision>
      <origin rpy="0 0 0" xyz="0 0 0.020"/>
      <geometry name="thproximal_collision_geom">
        <cylinder length="0.018" radius="0.012"/>
      </geometry>
    </collision>
  </link>
  <joint name="THJ4" type="revolute">
    <parent link="thbase"/>
    <child link="thproximal"/>
    <origin rpy="0 0 0" xyz="0 0 0"/>
    <axis xyz="1.0 0 0"/>
    <limit effort="1000" lower="0" upper="1.2217304764" velocity="10.0"/>
    <dynamics damping="1.0"/>
  </joint>
  <transmission name="thproximal_transmission" type="sr_mechanism_model/SimpleTransmission">
    <actuator name="THJ4"/>
    <joint name="THJ4"/>
  </transmission>
  <gazebo reference="thproximal">
    <sensor name="thproximal_contact" type="contact">
      <always_on>1</always_on>
      <update_rate>1000.0</update_rate>
      <contact>
        <collision>thproximal_collision</collision>
        <topic>thproximal_collision</topic>
      </contact>
      <plugin filename="libgazebo_ros_bumper.so" name="thproximal_gazebo_ros_bumper_controller">
        <alwaysOn>true</alwaysOn>
        <frameName>thproximal</frameName>
        <updateRate>100.0</updateRate>
        <bumperTopicName>contacts/th/proximal</bumperTopicName>
      </plugin>
    </sensor>
    <selfCollide>false</selfCollide>
    <material>LightGrey</material>
  </gazebo>
  <link name="thhub">
    <inertial>
      <mass value="0.002"/>
      <origin rpy="0 0 0" xyz="0 0 0"/>
      <inertia ixx="1e-7" ixy="0.0" ixz="0.0" iyy="1e-7" iyz="0.0" izz="1e-7"/>
    </inertial>
    <visual>
      <origin rpy="0 0 0" xyz="0 0 0"/>
      <geometry name="thhub_visual">
        <box size="0.001 0.001 0.001"/>
      </geometry>
      <material name="shadow_thhub_material">
        <color rgba="0.7 0.7 0.7 1.0"/>
      </material>
    </visual>
    <collision>
      <origin rpy="0 0 0 " xyz="0 0 0"/>
      <geometry name="thhub_collision_geom">
        <sphere radius="0.010"/>
      </geometry>
    </collision>
  </link>
  <joint name="THJ3" type="revolute">
    <parent link="thproximal"/>
    <child link="thhub"/>
    <origin rpy="0 0 0" xyz="0 0 0.038"/>
    <axis xyz="1 0 0"/>
    <limit effort="1000" lower="-0.209439510239" upper="0.209439510239" velocity="10.0"/>
    <dynamics damping="1.0"/>
  </joint>
  <transmission name="thhub_transmission" type="sr_mechanism_model/SimpleTransmission">
    <actuator name="THJ3"/>
    <joint name="THJ3"/>
  </transmission>
  <gazebo reference="thhub">
    <sensor name="thhub_contact" type="contact">
      <always_on>1</always_on>
      <update_rate>1000.0</update_rate>
      <contact>
        <collision>thhub_collision</collision>
        <topic>thhub_collision</topic>
      </contact>
      <plugin filename="libgazebo_ros_bumper.so" name="thhub_gazebo_ros_bumper_controller">
        <alwaysOn>true</alwaysOn>
        <frameName>thhub</frameName>
        <updateRate>100.0</updateRate>
        <bumperTopicName>contacts/th/hub</bumperTopicName>
      </plugin>
    </sensor>
    <selfCollide>true</selfCollide>
    <material>LightGrey</material>
  </gazebo>
  <link name="thmiddle">
    <inertial>
      <mass value="0.016"/>
      <origin rpy="0 0 0" xyz="0 0 0.016"/>
      <inertia ixx="1e-6" ixy="0.0" ixz="0.0" iyy="1e-6" iyz="0.0" izz="1e-6"/>
    </inertial>
    <visual>
      <origin rpy="0 0 0" xyz="0 0 0"/>
      <geometry name="thmiddle_visual">
        <mesh filename="package://sr_description/hand/model/TH2_z.dae" scale="0.001 0.001 0.001"/>
      </geometry>
      <material name="shadow_thmiddle_material">
        <color rgba="0.2 0.2 0.2 1.0"/>
      </material>
    </visual>
    <collision>
      <origin rpy="0 0 0 " xyz="0 0 0.012"/>
      <geometry name="thmiddle_collision_geom">
        <cylinder length="0.018" radius="0.011"/>
      </geometry>
    </collision>
    <collision>
      <origin rpy="0 0 0 " xyz="0 0 0.019"/>
      <geometry>
        <sphere radius="0.011"/>
      </geometry>
    </collision>
  </link>
  <joint name="THJ2" type="revolute">
    <parent link="thhub"/>
    <child link="thmiddle"/>
    <origin rpy="0 0 0" xyz="0 0 0"/>
    <axis xyz="0 -1 0"/>
    <limit effort="1000" lower="-0.698131700798" upper="0.698131700798" velocity="10.0"/>
    <dynamics damping="1.0"/>
  </joint>
  <transmission name="thmiddle_transmission" type="sr_mechanism_model/SimpleTransmission">
    <actuator name="THJ2"/>
    <joint name="THJ2"/>
  </transmission>
  <gazebo reference="thmiddle">
    <sensor name="thmiddle_contact" type="contact">
      <always_on>1</always_on>
      <update_rate>1000.0</update_rate>
      <contact>
        <collision>thmiddle_collision</collision>
        <topic>thmiddle_collision</topic>
      </contact>
      <plugin filename="libgazebo_ros_bumper.so" name="thmiddle_gazebo_ros_bumper_controller">
        <alwaysOn>true</alwaysOn>
        <frameName>thmiddle</frameName>
        <updateRate>100.0</updateRate>
        <bumperTopicName>contacts/th/middle</bumperTopicName>
      </plugin>
    </sensor>
    <selfCollide>true</selfCollide>
    <material>LightGrey</material>
  </gazebo>
  <link name="thdistal">
    <inertial>
      <mass value="0.016"/>
      <origin rpy="0 0 0" xyz="0 0 0.01375"/>
      <inertia ixx="9e-7" ixy="0.0" ixz="0.0" iyy="9e-7" iyz="0.0" izz="9e-7"/>
    </inertial>
    <visual>
      <origin rpy="0 0 0" xyz="0 0 0"/>
      <geometry name="thdistal_visual">
        <mesh filename="package://sr_description/hand/model/TH1_z.dae" scale="0.001 0.001 0.001"/>
      </geometry>
      <material name="shadow_thmiddle_material">
        <color rgba="0.2 0.2 0.2 1.0"/>
      </material>
    </visual>
    <collision>
      <origin rpy="0 0 0 " xyz="0 0 0"/>
      <geometry name="thmiddle_collision_geom">
        <mesh filename="package://sr_description/hand/model/TH1_z.dae" scale="0.001 0.001 0.001"/>
        <!--	  <box size="0.015 0.015 0.015" /> -->
      </geometry>
    </collision>
  </link>
  <joint name="THJ1" type="revolute">
    <parent link="thmiddle"/>
    <child link="thdistal"/>
    <origin rpy="0 0 -1.57079632679" xyz="0 0 0.032"/>
    <axis xyz="1 0 0"/>
    <limit effort="1000" lower="0" upper="1.57079632679" velocity="10.0"/>
    <dynamics damping="1.0"/>
  </joint>
  <link name="thtip">
    <inertial>
      <mass value="0.001"/>
      <inertia ixx="1e-7" ixy="0.0" ixz="0.0" iyy="1e-7" iyz="0.0" izz="1e-7"/>
    </inertial>
  </link>
  <joint name="thtip" type="fixed">
    <parent link="thdistal"/>
    <child link="thtip"/>
    <origin rpy="0 0 0" xyz="0 0 0.0275"/>
  </joint>
  <gazebo reference="thdistal">
    <sensor name="thdistal_contact" type="contact">
      <always_on>1</always_on>
      <update_rate>1000.0</update_rate>
      <contact>
        <collision>thdistal_collision</collision>
        <topic>thdistal_collision</topic>
      </contact>
      <plugin filename="libgazebo_ros_bumper.so" name="thdistal_gazebo_ros_bumper_controller">
        <alwaysOn>true</alwaysOn>
        <frameName>thdistal</frameName>
        <updateRate>100.0</updateRate>
        <bumperTopicName>contacts/th/distal</bumperTopicName>
      </plugin>
    </sensor>
    <mu1 value="500.0"/>
    <mu2 value="500.0"/>
    <kp value="10000000.0"/>
    <kd value="1.0"/>
    <material>LightGrey</material>
    <selfCollide>true</selfCollide>
  </gazebo>
  <transmission name="thdistal_transmission" type="sr_mechanism_model/SimpleTransmission">
    <actuator name="THJ1"/>
    <joint name="THJ1"/>
  </transmission>
</robot>

